Workbook

Sheet Summary
D2: Weekly Carrier X | N2: Yearly Carrier X
D3: Hammer Cost Per Unit | E3: Hammer Product Cost | F3: Transportation Cost Store 1 | G3: Total Cost | H3: Transportation Cost Store 2 | I3: Total Cost | J3: Total | N3: Hammer Cost Per Unit | O3: Hammer Product Cost | P3: Transportation Cost Store 1 | Q3: Total Cost | R3: Transportation Cost Store 2 | S3: Total Cost | T3: Total
C4: Supplier A | D4: 0.8 | E4: =(('Historical Orders'!$BG8) + ('Historical Orders'!$BQ8)) * (Summary!D4) -> 12837.44 | F4: ='Carrier Rates'!D2 -> 2540 | G4: =E4+F4 -> 15377.44 | H4: ='Carrier Rates'!D3 -> 1640 | I4: =E4+H4 -> 14477.44 | J4: =G4+I4 -> 29854.88 | M4: Supplier A | N4: 0.8 | O4: =(('Historical Orders'!$BG$54) + ('Historical Orders'!$BQ$54)) * (Summary!N4) -> 722770.4 | P4: ='Carrier Rates'!A16 -> 132080 | Q4: =O4+P4 -> 854850.4 | R4: ='Carrier Rates'!B16 -> 85280 | S4: =O4+R4 -> 808050.4 | T4: =Q4+S4 -> 1662900.8
C5: Supplier B | D5: 0.82 | E5: =(('Historical Orders'!$BG8) + ('Historical Orders'!$BQ8)) * (Summary!D5) -> 13158.376 | F5: ='Carrier Rates'!D4 -> 1200 | G5: =E5+F5 -> 14358.376 | H5: ='Carrier Rates'!D5 -> 1200 | I5: =E5+H5 -> 14358.376 | J5: =G5+I5 -> 28716.752 | M5: Supplier B | N5: 0.82 | O5: =(('Historical Orders'!$BG$54) + ('Historical Orders'!$BQ$54)) * (Summary!N5) -> 740839.66 | P5: ='Carrier Rates'!C16 -> 62400 | Q5: =O5+P5 -> 803239.66 | R5: ='Carrier Rates'!D16 -> 62400 | S5: =O5+R5 -> 803239.66 | T5: =Q5+S5 -> 1606479.3
C6: Diff | D6: =D4-D5 -> -0.02 | E6: =E4-E5 -> -320.936 | F6: =F4-F5 -> 1340 | G6: =G4-G5 -> 1019.064 | H6: =H4-H5 -> 440 | I6: =I4-I5 -> 119.064 | J6: =J4-J5 -> 1138.128 | M6: Diff | N6: =N4-N5 -> -0.02 | O6: =O4-O5 -> -18069.26 | P6: =P4-P5 -> 69680 | Q6: =Q4-Q5 -> 51610.74 | R6: =R4-R5 -> 22880 | S6: =S4-S5 -> 4810.74 | T6: =T4-T5 -> 56421.48
D9: Weekly Carrier Y | N9: Yearly Carrier Y
D10: Hammer Cost Per Unit | E10: Hammer Product Cost | F10: Transportation Cost Store 1 | G10: Total Cost | H10: Transportation Cost Store 2 | I10: Total Cost | J10: Total | N10: Hammer Cost Per Unit | O10: Hammer Product Cost | P10: Transportation Cost Store 1 | Q10: Total Cost | R10: Transportation Cost Store 2 | S10: Total Cost | T10: Total
C11: Supplier A | D11: 0.8 | E11: =(('Historical Orders'!$BG8) + ('Historical Orders'!$BQ8)) * (Summary!D11) -> 12837.44 | F11: =(('Historical Orders'!$BG8) + ('Historical Orders'!$BQ8)) * ('Carrier Rates'!D6) -> 1925.616 | G11: =E11+F11 -> 14763.056 | H11: =(('Historical Orders'!$BG8) + ('Historical Orders'!$BQ8)) * ('Carrier Rates'!D8) -> 1123.276 | I11: =E11+H11 -> 13960.716 | J11: =G11+I11 -> 28723.772 | M11: Supplier A | N11: 0.8 | O11: =(('Historical Orders'!$BG$54) + ('Historical Orders'!$BQ$54)) * (Summary!N11) -> 722770.4 | P11: =(('Historical Orders'!$BG$54) + ('Historical Orders'!$BQ$54)) * ('Carrier Rates'!D6) -> 108415.56 | Q11: =O11+P11 -> 831185.96 | R11: =(('Historical Orders'!$BG$54) + ('Historical Orders'!$BQ$54)) * ('Carrier Rates'!D8) -> 63242.41 | S11: =O11+R11 -> 786012.81 | T11: =Q11+S11 -> 1617198.8
C12: Supplier B | D12: 0.82 | E12: =(('Historical Orders'!$BG8) + ('Historical Orders'!$BQ8)) * (Summary!D12) -> 13158.376 | F12: =(('Historical Orders'!$BG9) + ('Historical Orders'!$BQ9)) * ('Carrier Rates'!D7) -> 990.374 | G12: =E12+F12 -> 14148.75 | H12: =(('Historical Orders'!$BG9) + ('Historical Orders'!$BQ9)) * ('Carrier Rates'!D9) -> 848.892 | I12: =E12+H12 -> 14007.268 | J12: =G12+I12 -> 28156.018 | M12: Supplier B | N12: 0.82 | O12: =(('Historical Orders'!$BG$54) + ('Historical Orders'!$BQ$54)) * (Summary!N12) -> 740839.66 | P12: =(('Historical Orders'!$BG$54) + ('Historical Orders'!$BQ$54)) * ('Carrier Rates'!D7) -> 63242.41 | Q12: =O12+P12 -> 804082.07 | R12: =(('Historical Orders'!$BG$54) + ('Historical Orders'!$BQ$54)) * ('Carrier Rates'!D9) -> 54207.78 | S12: =O12+R12 -> 795047.44 | T12: =Q12+S12 -> 1599129.5
C13: Diff | D13: =D11-D12 -> -0.02 | E13: =E11-E12 -> -320.936 | F13: =F11-F12 -> 935.242 | G13: =G11-G12 -> 614.306 | H13: =H11-H12 -> 274.384 | I13: =I11-I12 -> -46.552 | J13: =J11-J12 -> 567.754 | M13: Diff | N13: =N11-N12 -> -0.02 | O13: =O11-O12 -> -18069.26 | P13: =P11-P12 -> 45173.15 | Q13: =Q11-Q12 -> 27103.89 | R13: =R11-R12 -> 9034.63 | S13: =S11-S12 -> -9034.63 | T13: =T11-T12 -> 18069.26

Sheet Future 2016 - 10% of Summary
D2: Weekly Carrier X | N2: Yearly Carrier X
D3: Hammer Cost Per Unit | E3: Hammer Product Cost | F3: Transportation Cost Store 1 | G3: Total Cost | H3: Transportation Cost Store 2 | I3: Total Cost | J3: Total Dif | N3: Hammer Cost Per Unit | O3: Hammer Product Cost | P3: Transportation Cost Store 1 | Q3: Total Cost | R3: Transportation Cost Store 2 | S3: Total Cost | T3: Total
C4: Supplier A | D4: 0.8 | E4: =(('Future Orders'!$BI8) + ('Future Orders'!$BU8)) * ('Future 2016 - 10% of Summary'!D4) -> 14121.184 | F4: ='Carrier Rates'!D2 -> 2540 | G4: =E4+F4 -> 16661.184 | H4: ='Carrier Rates'!D3 -> 1640 | I4: =E4+H4 -> 15761.184 | J4: =G4+I4 -> 32422.368 | M4: Supplier A | N4: 0.8 | O4: =(('Future Orders'!$BI$54) + ('Future Orders'!$BU$54)) * ('Future 2016 - 10% of Summary'!N4) -> 795047.44 | P4: ='Carrier Rates'!A16 -> 132080 | Q4: =O4+P4 -> 927127.44 | R4: ='Carrier Rates'!B16 -> 85280 | S4: =O4+R4 -> 880327.44 | T4: =Q4+S4 -> 1807454.9
C5: Supplier B | D5: 0.82 | E5: =(('Future Orders'!$BI8) + ('Future Orders'!$BU8))*('Future 2016 - 10% of Summary'!D5) -> 14474.214 | F5: ='Carrier Rates'!D4 -> 1200 | G5: =E5+F5 -> 15674.214 | H5: ='Carrier Rates'!D5 -> 1200 | I5: =E5+H5 -> 15674.214 | J5: =G5+I5 -> 31348.427 | M5: Supplier B | N5: 0.82 | O5: =(('Future Orders'!$BI$54) + ('Future Orders'!$BU$54)) * ('Future 2016 - 10% of Summary'!N5) -> 814923.63 | P5: ='Carrier Rates'!C16 -> 62400 | Q5: =O5+P5 -> 877323.63 | R5: ='Carrier Rates'!D16 -> 62400 | S5: =O5+R5 -> 877323.63 | T5: =Q5+S5 -> 1754647.3
C6: Diff | D6: =D4-D5 -> -0.02 | E6: =E4-E5 -> -353.0296 | F6: =F4-F5 -> 1340 | G6: =G4-G5 -> 986.9704 | H6: =H4-H5 -> 440 | I6: =I4-I5 -> 86.9704 | J6: =J4-J5 -> 1073.9408 | M6: Diff | N6: =N4-N5 -> -0.02 | O6: =O4-O5 -> -19876.186 | P6: =P4-P5 -> 69680 | Q6: =Q4-Q5 -> 49803.814 | R6: =R4-R5 -> 22880 | S6: =S4-S5 -> 3003.814 | T6: =T4-T5 -> 52807.628
D9: Weekly Carrier Y | N9: Yearly Carrier Y
D10: Hammer Cost Per Unit | E10: Hammer Product Cost | F10: Transportation Cost Store 1 | G10: Total Cost | H10: Transportation Cost Store 2 | I10: Total Cost | J10: Total Dif | N10: Hammer Cost Per Unit | O10: Hammer Product Cost | P10: Transportation Cost Store 1 | Q10: Total Cost | R10: Transportation Cost Store 2 | S10: Total Cost | T10: Total
C11: Supplier A | D11: 0.8 | E11: =(('Future Orders'!$BI8) + ('Future Orders'!$BU8))*('Future 2016 - 10% of Summary'!D11) -> 14121.184 | F11: =(('Future Orders'!$BI8) + ('Future Orders'!$BU8)) * ('Carrier Rates'!D6) -> 2118.1776 | G11: =E11+F11 -> 16239.362 | H11: =(('Future Orders'!$BI8) + ('Future Orders'!$BU8)) * ('Carrier Rates'!D8) -> 1235.6036 | I11: =E11+H11 -> 15356.788 | J11: =G11+I11 -> 31596.149 | M11: Supplier A | N11: 0.8 | O11: =(('Future Orders'!$BI$54) + ('Future Orders'!$BU$54)) * ('Future 2016 - 10% of Summary'!N11) -> 795047.44 | P11: =(('Future Orders'!$BI$54) + ('Future Orders'!$BU$54)) * ('Carrier Rates'!D6) -> 119257.12 | Q11: =O11+P11 -> 914304.56 | R11: =(('Future Orders'!$BI$54) + ('Future Orders'!$BU$54)) * ('Carrier Rates'!D8) -> 69566.651 | S11: =O11+R11 -> 864614.09 | T11: =Q11+S11 -> 1778918.6
C12: Supplier B | D12: 0.82 | E12: =(('Future Orders'!$BI8) + ('Future Orders'!$BU8))*('Future 2016 - 10% of Summary'!D12) -> 14474.214 | F12: =(('Future Orders'!$BI9) + ('Future Orders'!$BU9)) * ('Carrier Rates'!D7) -> 1089.4114 | G12: =E12+F12 -> 15563.625 | H12: =(('Future Orders'!$BI8) + ('Future Orders'!$BU8)) * ('Carrier Rates'!D9) -> 1059.0888 | I12: =E12+H12 -> 15533.302 | J12: =G12+I12 -> 31096.927 | M12: Supplier B | N12: 0.82 | O12: =(('Future Orders'!$BI$54) + ('Future Orders'!$BU$54)) * ('Future 2016 - 10% of Summary'!N12) -> 814923.63 | P12: =(('Future Orders'!$BI$54) + ('Future Orders'!$BU$54)) * ('Carrier Rates'!D7) -> 69566.651 | Q12: =O12+P12 -> 884490.28 | R12: =(('Future Orders'!$BI$54) + ('Future Orders'!$BU$54)) * ('Carrier Rates'!D9) -> 59628.558 | S12: =O12+R12 -> 874552.18 | T12: =Q12+S12 -> 1759042.5
C13: Diff | D13: =D11-D12 -> -0.02 | E13: =E11-E12 -> -353.0296 | F13: =F11-F12 -> 1028.7662 | G13: =G11-G12 -> 675.7366 | H13: =H11-H12 -> 176.5148 | I13: =I11-I12 -> -176.5148 | J13: =J11-J12 -> 499.2218 | M13: Diff | N13: =N11-N12 -> -0.02 | O13: =O11-O12 -> -19876.186 | P13: =P11-P12 -> 49690.465 | Q13: =Q11-Q12 -> 29814.279 | R13: =R11-R12 -> 9938.093 | S13: =S11-S12 -> -9938.093 | T13: =T11-T12 -> 19876.186

Sheet Future 2017 - 20% of Summary
D2: Weekly Carrier X | N2: Yearly Carrier X
D3: Hammer Cost Per Unit | E3: Hammer Product Cost | F3: Transportation Cost Store 1 | G3: Total Cost | H3: Transportation Cost Store 2 | I3: Total Cost | J3: Total | N3: Hammer Cost Per Unit | O3: Hammer Product Cost | P3: Transportation Cost Store 1 | Q3: Total Cost | R3: Transportation Cost Store 2 | S3: Total Cost | T3: Total
C4: Supplier A | D4: 0.8 | E4: =((('Future Orders'!$BI8) + ('Future Orders'!$BU8)) * 1.1) * ('Future 2017 - 20% of Summary'!D4) -> 15533.302 | F4: ='Carrier Rates'!D2 -> 2540 | G4: =E4+F4 -> 18073.302 | H4: ='Carrier Rates'!D3 -> 1640 | I4: =E4+H4 -> 17173.302 | J4: =G4+I4 -> 35246.605 | M4: Supplier A | N4: 0.8 | O4: =((('Future Orders'!$BI$54) + ('Future Orders'!$BU$54)) * 1.1) * ('Future 2017 - 20% of Summary'!N4) -> 874552.18 | P4: ='Carrier Rates'!A16 -> 132080 | Q4: =O4+P4 -> 1006632.2 | R4: ='Carrier Rates'!B16 -> 85280 | S4: =O4+R4 -> 959832.18 | T4: =Q4+S4 -> 1966464.4
C5: Supplier B | D5: 0.82 | E5: =((('Future Orders'!$BI8) + ('Future Orders'!$BU8)) * 1.1) * ('Future 2017 - 20% of Summary'!D5) -> 15921.635 | F5: ='Carrier Rates'!D4 -> 1200 | G5: =E5+F5 -> 17121.635 | H5: ='Carrier Rates'!D5 -> 1200 | I5: =E5+H5 -> 17121.635 | J5: =G5+I5 -> 34243.27 | M5: Supplier B | N5: 0.82 | O5: =((('Future Orders'!$BI$54) + ('Future Orders'!$BU$54)) * 1.1) * ('Future 2017 - 20% of Summary'!N5) -> 896415.99 | P5: ='Carrier Rates'!C16 -> 62400 | Q5: =O5+P5 -> 958815.99 | R5: ='Carrier Rates'!D16 -> 62400 | S5: =O5+R5 -> 958815.99 | T5: =Q5+S5 -> 1917632
C6: Diff | D6: =D4-D5 -> -0.02 | E6: =E4-E5 -> -388.33256 | F6: =F4-F5 -> 1340 | G6: =G4-G5 -> 951.66744 | H6: =H4-H5 -> 440 | I6: =I4-I5 -> 51.66744 | J6: =J4-J5 -> 1003.3349 | M6: Diff | N6: =N4-N5 -> -0.02 | O6: =O4-O5 -> -21863.805 | P6: =P4-P5 -> 69680 | Q6: =Q4-Q5 -> 47816.195 | R6: =R4-R5 -> 22880 | S6: =S4-S5 -> 1016.1954 | T6: =T4-T5 -> 48832.391
D9: Weekly Carrier Y | N9: Yearly Carrier Y
D10: Hammer Cost Per Unit | E10: Hammer Product Cost | F10: Transportation Cost Store 1 | G10: Total Cost | H10: Transportation Cost Store 2 | I10: Total Cost | J10: Total | N10: Hammer Cost Per Unit | O10: Hammer Product Cost | P10: Transportation Cost Store 1 | Q10: Total Cost | R10: Transportation Cost Store 2 | S10: Total Cost | T10: Total
C11: Supplier A | D11: 0.8 | E11: =((('Future Orders'!$BI8) + ('Future Orders'!$BU8)) * 1.1) * ('Future 2017 - 20% of Summary'!D11) -> 15533.302 | F11: =((('Future Orders'!$BI8) + ('Future Orders'!$BU8)) * 1.1) * ('Carrier Rates'!D6) -> 2329.9954 | G11: =E11+F11 -> 17863.298 | H11: =((('Future Orders'!$BI8) + ('Future Orders'!$BU8)) * 1.1) * ('Carrier Rates'!D8) -> 1359.164 | I11: =E11+H11 -> 16892.466 | J11: =G11+I11 -> 34755.764 | M11: Supplier A | N11: 0.8 | O11: =((('Future Orders'!$BI$54) + ('Future Orders'!$BU$54)) * 1.1) * ('Future 2017 - 20% of Summary'!N11) -> 874552.18 | P11: =((('Future Orders'!$BI$54) + ('Future Orders'!$BU$54)) * 1.1) * ('Carrier Rates'!D6) -> 131182.83 | Q11: =O11+P11 -> 1005735 | R11: =((('Future Orders'!$BI$54) + ('Future Orders'!$BU$54))* 1.1) * ('Carrier Rates'!D8) -> 76523.316 | S11: =O11+R11 -> 951075.5 | T11: =Q11+S11 -> 1956810.5
C12: Supplier B | D12: 0.82 | E12: =((('Future Orders'!$BI8) + ('Future Orders'!$BU8)) * 1.1) * ('Future 2017 - 20% of Summary'!D12) -> 15921.635 | F12: =((('Future Orders'!$BI8) + ('Future Orders'!$BU8)) * 1.1) * ('Carrier Rates'!D7) -> 1359.164 | G12: =E12+F12 -> 17280.799 | H12: =((('Future Orders'!$BI8) + ('Future Orders'!$BU8)) * 1.1) * ('Carrier Rates'!D9) -> 1164.9977 | I12: =E12+H12 -> 17086.633 | J12: =G12+I12 -> 34367.432 | M12: Supplier B | N12: 0.82 | O12: =((('Future Orders'!$BI$54) + ('Future Orders'!$BU$54)) * 1.1) * ('Future 2017 - 20% of Summary'!N12) -> 896415.99 | P12: =((('Future Orders'!$BI$54) + ('Future Orders'!$BU$54))* 1.1) * ('Carrier Rates'!D7) -> 76523.316 | Q12: =O12+P12 -> 972939.3 | R12: =((('Future Orders'!$BI$54) + ('Future Orders'!$BU$54))* 1.1) * ('Carrier Rates'!D9) -> 65591.414 | S12: =O12+R12 -> 962007.4 | T12: =Q12+S12 -> 1934946.7
C13: Diff | D13: =D11-D12 -> -0.02 | E13: =E11-E12 -> -388.33256 | F13: =F11-F12 -> 970.8314 | G13: =G11-G12 -> 582.49884 | H13: =H11-H12 -> 194.16628 | I13: =I11-I12 -> -194.16628 | J13: =J11-J12 -> 388.33256 | M13: Diff | N13: =N11-N12 -> -0.02 | O13: =O11-O12 -> -21863.805 | P13: =P11-P12 -> 54659.512 | Q13: =Q11-Q12 -> 32795.707 | R13: =R11-R12 -> 10931.902 | S13: =S11-S12 -> -10931.902 | T13: =T11-T12 -> 21863.805

Sheet Future 2020 - 50% of Summary
D2: Weekly Carrier X | N2: Yearly Carrier X
D3: Hammer Cost Per Unit | E3: Hammer Product Cost | F3: Transportation Cost Store 1 | G3: Total Cost | H3: Transportation Cost Store 2 | I3: Total Cost | J3: Total | N3: Hammer Cost Per Unit | O3: Hammer Product Cost | P3: Transportation Cost Store 1 | Q3: Total Cost | R3: Transportation Cost Store 2 | S3: Total Cost | T3: Total
C4: Supplier A | D4: 0.8 | E4: =((('Future Orders'!$BI8) + ('Future Orders'!$BU8)) * 1.4) * ('Future 2020 - 50% of Summary'!D4) -> 19769.658 | F4: =('Carrier Rates'!D2) * 2 -> 5080 | G4: =E4+F4 -> 24849.658 | H4: =('Carrier Rates'!D3) * 2 -> 3280 | I4: =E4+H4 -> 23049.658 | J4: =G4+I4 -> 47899.315 | M4: Supplier A | N4: 0.8 | O4: =((('Future Orders'!$BI$54) + ('Future Orders'!$BU$54)) * 1.4) * ('Future 2020 - 50% of Summary'!N4) -> 1113066.4 | P4: =('Carrier Rates'!A16) * 2 -> 264160 | Q4: =O4+P4 -> 1377226.4 | R4: =('Carrier Rates'!B16) * 2 -> 170560 | S4: =O4+R4 -> 1283626.4 | T4: =Q4+S4 -> 2660852.8
C5: Supplier B | D5: 0.82 | E5: =((('Future Orders'!$BI8) + ('Future Orders'!$BU8)) * 1.4) * ('Future 2020 - 50% of Summary'!D5) -> 20263.899 | F5: =('Carrier Rates'!D4) * 2 -> 2400 | G5: =E5+F5 -> 22663.899 | H5: =('Carrier Rates'!D5) * 2 -> 2400 | I5: =E5+H5 -> 22663.899 | J5: =G5+I5 -> 45327.798 | M5: Supplier B | N5: 0.82 | O5: =((('Future Orders'!$BI$54) + ('Future Orders'!$BU$54)) * 1.4) * ('Future 2020 - 50% of Summary'!N5) -> 1140893.1 | P5: =('Carrier Rates'!C16) * 2 -> 124800 | Q5: =O5+P5 -> 1265693.1 | R5: =('Carrier Rates'!D16) * 2 -> 124800 | S5: =O5+R5 -> 1265693.1 | T5: =Q5+S5 -> 2531386.2
C6: Diff | D6: =D4-D5 -> -0.02 | E6: =E4-E5 -> -494.24144 | F6: =F4-F5 -> 2680 | G6: =G4-G5 -> 2185.7586 | H6: =H4-H5 -> 880 | I6: =I4-I5 -> 385.75856 | J6: =J4-J5 -> 2571.5171 | M6: Diff | N6: =N4-N5 -> -0.02 | O6: =O4-O5 -> -27826.66 | P6: =P4-P5 -> 139360 | Q6: =Q4-Q5 -> 111533.34 | R6: =R4-R5 -> 45760 | S6: =S4-S5 -> 17933.34 | T6: =T4-T5 -> 129466.68
D9: Weekly Carrier Y | N9: Yearly Carrier Y
D10: Hammer Cost Per Unit | E10: Hammer Product Cost | F10: Transportation Cost Store 1 | G10: Total Cost | H10: Transportation Cost Store 2 | I10: Total Cost | J10: Total | N10: Hammer Cost Per Unit | O10: Hammer Product Cost | P10: Transportation Cost Store 1 | Q10: Total Cost | R10: Transportation Cost Store 2 | S10: Total Cost | T10: Total
C11: Supplier A | D11: 0.8 | E11: =((('Future Orders'!$BI8) + ('Future Orders'!$BU8)) * 1.4) * ('Future 2020 - 50% of Summary'!D11) -> 19769.658 | F11: =((('Future Orders'!$BI8) + ('Future Orders'!$BU8)) * 1.4) * ('Carrier Rates'!D6) -> 2965.4486 | G11: =E11+F11 -> 22735.106 | H11: =((('Future Orders'!$BI8) + ('Future Orders'!$BU8)) * 1.4) * ('Carrier Rates'!D8) -> 1729.845 | I11: =E11+H11 -> 21499.503 | J11: =G11+I11 -> 44234.609 | M11: Supplier A | N11: 0.8 | O11: =((('Future Orders'!$BI$54) + ('Future Orders'!$BU$54)) * 1.4) * ('Future 2020 - 50% of Summary'!N11) -> 1113066.4 | P11: =((('Future Orders'!$BI$54) + ('Future Orders'!$BU$54)) * 1.4) * ('Carrier Rates'!D6) -> 166959.96 | Q11: =O11+P11 -> 1280026.4 | R11: =((('Future Orders'!$BI$54) + ('Future Orders'!$BU$54)) * 1.4) * ('Carrier Rates'!D8) -> 97393.311 | S11: =O11+R11 -> 1210459.7 | T11: =Q11+S11 -> 2490486.1
C12: Supplier B | D12: 0.82 | E12: =((('Future Orders'!$BI8) + ('Future Orders'!$BU8)) * 1.4) * ('Future 2020 - 50% of Summary'!D12) -> 20263.899 | F12: =((('Future Orders'!$BI8) + ('Future Orders'!$BU8)) * 1.4) * ('Carrier Rates'!D7) -> 1729.845 | G12: =E12+F12 -> 21993.744 | H12: =((('Future Orders'!$BI8) + ('Future Orders'!$BU8)) * 1.4) * ('Carrier Rates'!D9) -> 1482.7243 | I12: =E12+H12 -> 21746.623 | J12: =G12+I12 -> 43740.367 | M12: Supplier B | N12: 0.82 | O12: =((('Future Orders'!$BI$54) + ('Future Orders'!$BU$54)) * 1.4) * ('Future 2020 - 50% of Summary'!N12) -> 1140893.1 | P12: =((('Future Orders'!$BI$54) + ('Future Orders'!$BU$54)) * 1.4) * ('Carrier Rates'!D7) -> 97393.311 | Q12: =O12+P12 -> 1238286.4 | R12: =((('Future Orders'!$BI$54) + ('Future Orders'!$BU$54)) * 1.4) * ('Carrier Rates'!D9) -> 83479.981 | S12: =O12+R12 -> 1224373.1 | T12: =Q12+S12 -> 2462659.4
C13: Diff | D13: =D11-D12 -> -0.02 | E13: =E11-E12 -> -494.24144 | F13: =F11-F12 -> 1235.6036 | G13: =G11-G12 -> 741.36216 | H13: =H11-H12 -> 247.12072 | I13: =I11-I12 -> -247.12072 | J13: =J11-J12 -> 494.24144 | M13: Diff | N13: =N11-N12 -> -0.02 | O13: =O11-O12 -> -27826.66 | P13: =P11-P12 -> 69566.651 | Q13: =Q11-Q12 -> 41739.991 | R13: =R11-R12 -> 13913.33 | S13: =S11-S12 -> -13913.33 | T13: =T11-T12 -> 27826.66

Sheet Product Info
B1: Product Id | C1: Product Desc | D1: Package Qty | E1: Weight | F1: Weight Unit of Measure
B2: 1 | C2: Wrench | D2: 1 | E2: 2.2 | F2: LB
B3: 2 | C3: Saw | D3: 1 | E3: 1.2 | F3: LB
B4: 3 | C4: Drill | D4: 1 | E4: 8.3 | F4: LB
B5: 4 | C5: Hammer | D5: 1 | E5: 2 | F5: LB
F7: Current Shipping Rates
C9: Current Shipping Store 1 | I9: Current Shipping Store 2
C12: Weight | I12: Weight
D13: =$C$2 -> Wrench | E13: =$C$3 -> Saw | F13: =$C$4 -> Drill | G13: Total | J13: =$C$2 -> Wrench | K13: =$C$3 -> Saw | L13: =$C$4 -> Drill | M13: Total
C14: Supplier A | D14: =SUM('Historical Orders'!$I$2:$I$313) -> 516927.4 | E14: =SUM('Historical Orders'!$Q$2:$Q$313) -> 354705.6 | F14: =SUM('Historical Orders'!$Y$2:$Y$313) -> 0 | G14: =SUM(D14:F14) -> 871633 | I14: Supplier A | J14: =SUM('Historical Orders'!$M$2:$M$313) -> 386535.6 | K14: =SUM('Historical Orders'!$U$2:$U$313) -> 370653.6 | L14: =SUM('Historical Orders'!$AC$2:$AC$313) -> 0 | M14: =SUM(J14:L14) -> 757189.2
C15: Supplier B | D15: =SUM('Historical Orders'!$K$2:$K$313) -> 0 | E15: =SUM('Historical Orders'!$S$2:$S$313) -> 0 | F15: =SUM('Historical Orders'!$AA$2:$AA$313) -> 903977.9 | G15: =SUM(D15:F15) -> 903977.9 | I15: Supplier B | J15: =SUM('Historical Orders'!$O$2:$O$313) -> 0 | K15: =SUM('Historical Orders'!$W$2:$W$313) -> 0 | L15: =SUM('Historical Orders'!$AE$2:$AE$313) -> 1126675.2 | M15: =SUM(J15:L15) -> 1126675.2
C16: Total: | G16: =(G14+G15) -> 1775610.9 | I16: Total: | M16: =(M14+M15) -> 1883864.4
C17: Quantity | I17: Quantity
D18: =$C$2 -> Wrench | E18: =$C$3 -> Saw | F18: =$C$4 -> Drill | G18: Total | J18: =$C$2 -> Wrench | K18: =$C$3 -> Saw | L18: =$C$4 -> Drill | M18: Total
C19: Supplier A | D19: =SUM('Historical Orders'!$H$2:$H$313) -> 234967 | E19: =SUM('Historical Orders'!$L$2:$L$313) -> 175698 | F19: =SUM('Historical Orders'!$AB$2:$AB$313) -> 0 | G19: =SUM(D19:F19) -> 410665 | I19: Supplier A | J19: =SUM('Historical Orders'!$L$2:$L$313) -> 175698 | K19: =SUM('Historical Orders'!$T$2:$T$313) -> 308878 | L19: =SUM('Historical Orders'!$AB$2:$AB$313) -> 0 | M19: =SUM(J19:L19) -> 484576
C20: Supplier B | D20: =SUM('Historical Orders'!$J$2:$J$313) -> 0 | E20: =SUM('Historical Orders'!$R$2:$R$313) -> 0 | F20: =SUM('Historical Orders'!$Z$2:$Z$313) -> 108913 | G20: =SUM(D20:F20) -> 108913 | I20: Supplier B | J20: =SUM('Historical Orders'!$N$2:$N$313) -> 0 | K20: =SUM('Historical Orders'!$V$2:$V$313) -> 0 | L20: =SUM('Historical Orders'!$AD$2:$AD$313) -> 135744 | M20: =SUM(J20:L20) -> 135744
C21: Total: | G21: =(G19+G20) -> 519578 | I21: Total: | M21: =(M19+M20) -> 620320
C24: Supplier A Store 1 | I24: Supplier B Store 1
C25: Cost | I25: Weight
D26: =$C$2 -> Wrench | E26: =$C$3 -> Saw | F26: =$C$4 -> Drill | G26: Total | J26: =$C$2 -> Wrench | K26: =$C$3 -> Saw | L26: =$C$4 -> Drill | M26: Total
C27: Carrier X Cost | D27: ='Carrier Rates'!A16 -> 132080 | G27: =SUM(D27:F27) -> 132080 | I27: Carrier X Cost | L27: ='Carrier Rates'!C16 -> 62400 | M27: =SUM(J27:L27) -> 62400
C28: Carrier Y Cost | D28: =(D14)*('Carrier Rates'!$D$6) -> 62031.288 | E28: =(E14)*('Carrier Rates'!$D$6) -> 42564.672 | F28: =(F14)*('Carrier Rates'!$D$6) -> 0 | G28: =SUM(D28:F28) -> 104595.96 | I28: Carrier Y Cost | J28: =(D15)*('Carrier Rates'!$D$8) -> 0 | K28: =(E15)*('Carrier Rates'!$D$8) -> 0 | L28: =(F15)*('Carrier Rates'!$D$8) -> 63278.453 | M28: =SUM(J28:L28) -> 63278.453
C29: Difference: | G29: =(G27-G28) -> 27484.04 | I29: Difference: | M29: =(M27-M28) -> -878.453
C31: Supplier A Store 2 | I31: Supplier B Store 2
C32: Cost | I32: Weight
D33: =$C$2 -> Wrench | E33: =$C$3 -> Saw | F33: =$C$4 -> Drill | G33: Total | J33: =$C$2 -> Wrench | K33: =$C$3 -> Saw | L33: =$C$4 -> Drill | M33: Total
C34: Carrier X Cost | D34: ='Carrier Rates'!B16 -> 85280 | G34: =SUM(D34:F34) -> 85280 | I34: Carrier X Cost | L34: ='Carrier Rates'!D16 -> 62400 | M34: =SUM(J34:L34) -> 62400
C35: Carrier Y Cost | D35: =(J14)*('Carrier Rates'!$D$7) -> 27057.492 | E35: =(K14)*('Carrier Rates'!$D$7) -> 25945.752 | F35: =(L14)*('Carrier Rates'!$D$7) -> 0 | G35: =SUM(D35:F35) -> 53003.244 | I35: Carrier Y Cost | J35: =(J15)*('Carrier Rates'!$D$9) -> 0 | K35: =(K15)*('Carrier Rates'!$D$9) -> 0 | L35: =(L15)*('Carrier Rates'!$D$9) -> 67600.512 | M35: =SUM(J35:L35) -> 67600.512
C36: Difference: | G36: =(G34-G35) -> 32276.756 | I36: Difference: | M36: =SUM(M34-M35) -> -5200.512
F40: Proposed Shipping Rates
C42: Proposed Shipping Store 1 | J42: Proposed Shipping Store 2
C45: Weight | J45: Weight
D46: =$C$2 -> Wrench | E46: =$C$3 -> Saw | F46: =$C$4 -> Drill | G46: =$C$5 -> Hammer | H46: Total | K46: =$C$2 -> Wrench | L46: =$C$3 -> Saw | M46: =$C$4 -> Drill | N46: =$C$5 -> Hammer | O46: Total
C47: Supplier A | D47: =SUM('Future Orders'!$BI$54) -> 568620.14 | E47: =SUM('Future Orders'!$BJ$54) -> 390176.16 | F47: =SUM('Future Orders'!$BK$54) -> 0 | G47: =SUM('Future Orders'!$BL$54) -> 568620.14 | H47: =SUM(D47:G47) -> 1527416.4 | J47: Supplier A | K47: =SUM('Future Orders'!$BU$54) -> 425189.16 | L47: =SUM('Future Orders'!$BV$54) -> 407718.96 | M47: =SUM('Future Orders'!$BW$54) -> 0 | N47: =SUM('Future Orders'!$BX$54) -> 425189.16 | O47: =SUM(K47:N47) -> 1258097.3
C48: Supplier B | D48: =SUM('Future Orders'!$BO$54) -> 0 | E48: =SUM('Future Orders'!$BP$54) -> 0 | F48: =SUM('Future Orders'!$BQ$54) -> 994375.69 | G48: =SUM('Future Orders'!$BR$54) -> 0 | H48: =SUM(D48:G48) -> 994375.69 | J48: Supplier B | K48: =SUM('Future Orders'!$CA$54) -> 0 | L48: =SUM('Future Orders'!$CB$54) -> 0 | M48: =SUM('Future Orders'!$CC$54) -> 1239342.7 | N48: =SUM('Future Orders'!$CD$54) -> 0 | O48: =SUM(K48:N48) -> 1239342.7
C49: Total: | H49: =(H47+H48) -> 2521792.1 | J49: Total: | O49: =(O47+O48) -> 2497440
C50: Quantity | J50: Quantity
D51: =$C$2 -> Wrench | E51: =$C$3 -> Saw | F51: =$C$4 -> Drill | G51: =$C$5 -> Hammer | H51: Total | K51: =$C$2 -> Wrench | L51: =$C$3 -> Saw | M51: =$C$4 -> Drill | N51: =$C$5 -> Hammer | O51: Total
C52: Supplier A | D52: =SUM('Historical Orders'!$H$2:$H$313) -> 234967 | E52: =SUM('Historical Orders'!$L$2:$L$313) -> 175698 | F52: =SUM('Historical Orders'!$AB$2:$AB$313) -> 0 | G52: =SUM('Historical Orders'!$H$2:$H$313) -> 234967 | H52: =SUM(D52:G52) -> 645632 | J52: Supplier A | K52: =SUM('Historical Orders'!$L$2:$L$313) -> 175698 | L52: =SUM('Historical Orders'!$T$2:$T$313) -> 308878 | M52: =SUM('Historical Orders'!$AB$2:$AB$313) -> 0 | N52: =SUM('Historical Orders'!$L$2:$L$313) -> 175698 | O52: =SUM(K52:N52) -> 660274
C53: Supplier B | D53: =SUM('Historical Orders'!$J$2:$J$313) -> 0 | E53: =SUM('Historical Orders'!$R$2:$R$313) -> 0 | F53: =SUM('Historical Orders'!$Z$2:$Z$313) -> 108913 | G53: =SUM('Historical Orders'!$AH$2:$AH$313) -> 0 | H53: =SUM(D53:G53) -> 108913 | J53: Supplier B | K53: =SUM('Historical Orders'!$N$2:$N$313) -> 0 | L53: =SUM('Historical Orders'!$V$2:$V$313) -> 0 | M53: =SUM('Historical Orders'!$AD$2:$AD$313) -> 135744 | N53: =SUM('Historical Orders'!$AL$2:$AL$313) -> 0 | O53: =SUM(K53:N53) -> 135744
...

Sheet Carrier Rates
A1: Carrier | B1: Supplier | C1: Str Nbr | D1: Cost | E1: Curent Yearly Cost
A2: X | B2: A | C2: 1 | D2: 2540 | E2: =A15*D2 -> 132080
A3: X | B3: A | C3: 2 | D3: 1640 | E3: =B15*D3 -> 85280
A4: X | B4: B | C4: 1 | D4: 1200 | E4: =C15*D4 -> 62400
A5: X | B5: B | C5: 2 | D5: 1200 | E5: =D15*D5 -> 62400
A6: Y | B6: A | C6: 1 | D6: 0.12 | E6: =E15*D6 -> 104595.96
A7: Y | B7: A | C7: 2 | D7: 0.07 | E7: =F15*D7 -> 53003.244
A8: Y | B8: B | C8: 1 | D8: 0.07 | E8: =G15*D8 -> 63278.453
A9: Y | B9: B | C9: 2 | D9: 0.06 | E9: =H15*D9 -> 67600.512
A11: Carrier X | E11: Carrier Y
A12: Yearly Shipments for Supplier A Store 1 | B12: Yearly Shipments for Supplier A Store 2 | C12: Yearly Shipments for Supplier B Store 1 | D12: Yearly Shipments for Supplier B Store 2 | E12: Yearly Shipments Weight for Supplier A Store 1 | F12: Yearly Shipments Weight for Supplier A Store 2 | G12: Yearly Shipments Weight for Supplier B Store 1 | H12: Yearly Shipments Weight for Supplier B Store 2
A15: {=SUM('Historical Shipments'!S2:S53/2)} -> 52 | B15: {=SUM('Historical Shipments'!T2:T53/2)} -> 52 | C15: {=SUM('Historical Shipments'!U2:U53/2)} -> 52 | D15: {=SUM('Historical Shipments'!V2:V53/2)} -> 52 | E15: ='Historical Shipments'!$K$54 -> 871633 | F15: ='Historical Shipments'!$L$54 -> 757189.2 | G15: ='Historical Shipments'!$M$54 -> 903977.9 | H15: ='Historical Shipments'!$N$54 -> 1126675.2
A16: =A15*D2 -> 132080 | B16: =B15*D3 -> 85280 | C16: =C15*D4 -> 62400 | D16: =D15*D5 -> 62400 | E16: =E15*D6 -> 104595.96 | F16: =F15*D7 -> 53003.244 | G16: =G15*D8 -> 63278.453 | H16: =H15*D9 -> 67600.512
A20: Carrier X Yearly Cost | B20: =SUM(E2:E5) -> 342160
A21: Carrier Y Yearly Cost | B21: =SUM(E6:E9) -> 288478.17

Sheet Historical Orders
A1: Order Dt | B1: Str Nbr | C1: Supplier | D1: Product Id | E1: Order Qty | F1: Product Weight | G1: Order Weight | H1: Product 1, Store 1, Supplier A | I1: Product 1, Store 1, Supplier A, Weight | J1: Product 1, Store 1, Supplier B | K1: Product 1, Store 1, Supplier B, Weight | L1: Product 1, Store 2, Supplier A | M1: Product 1, Store 2, Supplier A, Weight | N1: Product 1, Store 2, Supplier B | O1: Product 1, Store 2, Supplier B, Weight | P1: Product 2, Store 1, Supplier A | Q1: Product 2, Store 1, Supplier A, Weight | R1: Product 2, Store 1, Supplier B | S1: Product 2, Store 1, Supplier B, Weight | T1: Product 2, Store 2, Supplier A | U1: Product 2, Store 2, Supplier A, Weight | V1: Product 2, Store 2, Supplier B | W1: Product 2, Store 2, Supplier B, Weight | X1: Product 3, Store 1, Supplier A | Y1: Product 3, Store 1, Supplier A, Weight | Z1: Product 3, Store 1, Supplier B | AA1: Product 3, Store 1, Supplier B, Weight | AB1: Product 3, Store 2, Supplier A | AC1: Product 3, Store 2, Supplier A, Weight | AD1: Product 3, Store 2, Supplier B | AE1: Product 3, Store 2, Supplier B, Weight | AF1: Product 4, Store 1, Supplier A | AG1: Product 4, Store 1, Supplier A, Weight | AH1: Product 4, Store 1, Supplier B | AI1: Product 4, Store 1, Supplier B, Weight | AJ1: Product 4, Store 2, Supplier A | AK1: Product 4, Store 2, Supplier A, Weight | AL1: Product 4, Store 2, Supplier B | AM1: Product 4, Store 2, Supplier B, Weight | AN1: Total Weight Store 1 Supplier A | AO1: Total Weight Store 1 Supplier B | AP1: Total Weight Store 2 Supplier A | AQ1: Total Weight Store 2 Supplier A2 | AT1: Order Date | AU1: Split 1 | AV1: Order Date | AW1: Quantity Total per week | AX1: Quantity Total per week Store 1 | AY1: Quantity Total per week Store 2 | AZ1: Quantity Total per week Supplier A | BA1: Quantity Total per week Supplier B | BB1: Split 2 | BC1: Weight Total per week | BD1: Weight Total per week Store 1 | BE1: Weight Total per week Store 2 | BF1: Split 3 | BG1: Weight Total per week Store 1 Product 1 Supplier A | BH1: Weight Total per week Store 1 Product 2 Supplier A | BI1: Weight Total per week Store 1 Product 3 Supplier A | BJ1: Weight Total per week Store 1 Supplier A | BK1: Split 4 | BL1: Weight Total per week Store 1 Product 1 Supplier B | BM1: Weight Total per week Store 1 Product 2 Supplier B | BN1: Weight Total per week Store 1 Product 3 Supplier B | BO1: Weight Total per week Store 1 Supplier B | BP1: Split 5 | BQ1: Weight Total per week Store 2 Product 1 Supplier A | BR1: Weight Total per week Store 2 Product 2 Supplier A | BS1: Weight Total per week Store 2 Product 3 Supplier A | BT1: Weight Total per week Store 2 Supplier A | BU1: Split 6 | BV1: Weight Total per week Store 2 Product 1 Supplier B | BW1: Weight Total per week Store 2 Product 2 Supplier B | BX1: Weight Total per week Store 2 Product 3 Supplier B | BY1: Weight Total per week Store 2 Supplier B | BZ1: Split 7 | CA1: Store 1 per week | CB1: Store 2 per Week | CC1: Supplier A per week | CD1: Supplier B per week | CE1: Product ID 1 per week | CF1: Product ID 2 per week | CG1: Product ID 3 per week | CH1: Split 8
A2: 41855 | B2: 1 | C2: A | D2: 1 | E2: 4338 | F2: 2.2 | G2: 9543.6 | H2: =SUMIFS('Historical Orders'!$E2, 'Historical Orders'!$D2, "1", 'Historical Orders'!$C2, "A", 'Historical Orders'!$B2, "1") -> 4338 | I2: =SUMIFS('Historical Orders'!$G2, 'Historical Orders'!$D2, "1", 'Historical Orders'!$C2, "A", 'Historical Orders'!$B2, "1") -> 9543.6 | J2: =SUMIFS('Historical Orders'!$E2, 'Historical Orders'!$D2, "1", 'Historical Orders'!$C2, "B", 'Historical Orders'!$B2, "1") -> 0 | K2: =SUMIFS('Historical Orders'!$G2, 'Historical Orders'!$D2, "1", 'Historical Orders'!$C2, "B", 'Historical Orders'!$B2, "1") -> 0 | L2: =SUMIFS('Historical Orders'!$E2, 'Historical Orders'!$D2, "1", 'Historical Orders'!$C2, "A", 'Historical Orders'!$B2, "2") -> 0 | M2: =SUMIFS('Historical Orders'!$G2, 'Historical Orders'!$D2, "1", 'Historical Orders'!$C2, "A", 'Historical Orders'!$B2, "2") -> 0 | N2: =SUMIFS('Historical Orders'!$E2, 'Historical Orders'!$D2, "1", 'Historical Orders'!$C2, "B", 'Historical Orders'!$B2, "2") -> 0 | O2: =SUMIFS('Historical Orders'!$G2, 'Historical Orders'!$D2, "1", 'Historical Orders'!$C2, "B", 'Historical Orders'!$B2, "2") -> 0 | P2: =SUMIFS('Historical Orders'!$E2, 'Historical Orders'!$D2, "2", 'Historical Orders'!$C2, "A", 'Historical Orders'!$B2, "1") -> 0 | Q2: =SUMIFS('Historical Orders'!$G2, 'Historical Orders'!$D2, "2", 'Historical Orders'!$C2, "A", 'Historical Orders'!$B2, "1") -> 0 | R2: =SUMIFS('Historical Orders'!$E2, 'Historical Orders'!$D2, "2", 'Historical Orders'!$C2, "B", 'Historical Orders'!$B2, "1") -> 0 | S2: =SUMIFS('Historical Orders'!$G2, 'Historical Orders'!$D2, "2", 'Historical Orders'!$C2, "B", 'Historical Orders'!$B2, "1") -> 0 | T2: =SUMIFS('Historical Orders'!$E2, 'Historical Orders'!$D2, "2", 'Historical Orders'!$C2, "A", 'Historical Orders'!$B2, "2") -> 0 | U2: =SUMIFS('Historical Orders'!$G2, 'Historical Orders'!$D2, "2", 'Historical Orders'!$C2, "A", 'Historical Orders'!$B2, "2") -> 0 | V2: =SUMIFS('Historical Orders'!$E2, 'Historical Orders'!$D2, "2", 'Historical Orders'!$C2, "B", 'Historical Orders'!$B2, "2") -> 0 | W2: =SUMIFS('Historical Orders'!$G2, 'Historical Orders'!$D2, "2", 'Historical Orders'!$C2, "B", 'Historical Orders'!$B2, "2") -> 0 | X2: =SUMIFS('Historical Orders'!$E2, 'Historical Orders'!$D2, "3", 'Historical Orders'!$C2, "A", 'Historical Orders'!$B2, "1") -> 0 | Y2: =SUMIFS('Historical Orders'!$G2, 'Historical Orders'!$D2, "3", 'Historical Orders'!$C2, "A", 'Historical Orders'!$B2, "1") -> 0 | Z2: =SUMIFS('Historical Orders'!$E2, 'Historical Orders'!$D2, "3", 'Historical Orders'!$C2, "B", 'Historical Orders'!$B2, "1") -> 0 | AA2: =SUMIFS('Historical Orders'!$G2, 'Historical Orders'!$D2, "3", 'Historical Orders'!$C2, "B", 'Historical Orders'!$B2, "1") -> 0 | AB2: =SUMIFS('Historical Orders'!$E2, 'Historical Orders'!$D2, "3", 'Historical Orders'!$C2, "A", 'Historical Orders'!$B2, "2") -> 0 | AC2: =SUMIFS('Historical Orders'!$G2, 'Historical Orders'!$D2, "3", 'Historical Orders'!$C2, "A", 'Historical Orders'!$B2, "2") -> 0 | AD2: =SUMIFS('Historical Orders'!$E2, 'Historical Orders'!$D2, "3", 'Historical Orders'!$C2, "B", 'Historical Orders'!$B2, "2") -> 0 | AE2: =SUMIFS('Historical Orders'!$G2, 'Historical Orders'!$D2, "3", 'Historical Orders'!$C2, "B", 'Historical Orders'!$B2, "2") -> 0 | AF2: =SUMIFS('Historical Orders'!$E2, 'Historical Orders'!$D2, "4", 'Historical Orders'!$C2, "A", 'Historical Orders'!$B2, "1") -> 0 | AG2: =SUMIFS('Historical Orders'!$G2, 'Historical Orders'!$D2, "4", 'Historical Orders'!$C2, "A", 'Historical Orders'!$B2, "1") -> 0 | AH2: =SUMIFS('Historical Orders'!$E2, 'Historical Orders'!$D2, "4", 'Historical Orders'!$C2, "B", 'Historical Orders'!$B2, "1") -> 0 | AI2: =SUMIFS('Historical Orders'!$G2, 'Historical Orders'!$D2, "4", 'Historical Orders'!$C2, "B", 'Historical Orders'!$B2, "1") -> 0 | AJ2: =SUMIFS('Historical Orders'!$E2, 'Historical Orders'!$D2, "4", 'Historical Orders'!$C2, "A", 'Historical Orders'!$B2, "2") -> 0 | AK2: =SUMIFS('Historical Orders'!$G2, 'Historical Orders'!$D2, "4", 'Historical Orders'!$C2, "A", 'Historical Orders'!$B2, "2") -> 0 | AL2: =SUMIFS('Historical Orders'!$E2, 'Historical Orders'!$D2, "4", 'Historical Orders'!$C2, "B", 'Historical Orders'!$B2, "2") -> 0 | AM2: =SUMIFS('Historical Orders'!$G2, 'Historical Orders'!$D2, "4", 'Historical Orders'!$C2, "B", 'Historical Orders'!$B2, "2") -> 0 | AN2: =SUMIFS('Historical Orders'!$G2, 'Historical Orders'!$C2, "A", 'Historical Orders'!$B2, "1") -> 9543.6 | AO2: =SUMIFS('Historical Orders'!$G2, 'Historical Orders'!$C2, "B", 'Historical Orders'!$B2, "1") -> 0 | AP2: =SUMIFS('Historical Orders'!$G2, 'Historical Orders'!$C2, "A", 'Historical Orders'!$B2, "2") -> 0 | AQ2: =SUMIFS('Historical Orders'!$G2, 'Historical Orders'!$C2, "B", 'Historical Orders'!$B2, "2") -> 0 | AT2: {=UNIQUE('Historical Orders'!$A$2:$A$313)} -> 41855 | AV2: =AT2 -> 41855 | AW2: =SUMIFS(E:E, A:A, AT2) -> 22543 | AX2: =SUMIFS(E:E, A:A, AT2, B:B, "1") -> 11234 | AY2: =SUMIFS(E:E, A:A, AT2, B:B, "2") -> 11309 | AZ2: =SUMIFS(E:E, A:A, AT2, C:C, "A") -> 18117 | BA2: =SUMIFS(E:E, A:A, AT2, C:C, "B") -> 4426 | BC2: =SUMIFS(G:G, A:A, AT2) -> 66414.2 | BD2: =SUMIFS(G:G, A:A, AT2, B:B, "1") -> 31237.8 | BE2: =SUMIFS(G:G, A:A, AT2, B:B, "2") -> 35176.4 | BG2: =SUMIFS(G:G, A:A, AT2, B:B, "1", D:D, "1", C:C, "A") -> 9543.6 | BH2: =SUMIFS(G:G, A:A, AT2, B:B, "1", D:D, "2", C:C, "A") -> 6007.2 | BI2: =SUMIFS(G:G, A:A, AT2, B:B, "1", D:D, "3", C:C, "A") -> 0 | BJ2: =SUM('Historical Orders'!$BG2:$BI2) -> 15550.8 | BL2: =SUMIFS(G:G, A:A, AT2, B:B, "1", D:D, "1", C:C, "B") -> 0 | BM2: =SUMIFS(G:G, A:A, AT2, B:B, "1", D:D, "2", C:C, "B") -> 0 | BN2: =SUMIFS(G:G, A:A, AT2, B:B, "1", D:D, "3", C:C, "B") -> 15687 | BO2: =SUM('Historical Orders'!$BL2:$BN2) -> 15687 | BQ2: =SUMIFS(G:G, A:A, AT2, B:B, "2", D:D, "1", C:C, "A") -> 7920 | BR2: =SUMIFS(G:G, A:A, AT2, B:B, "2", D:D, "2", C:C, "A") -> 6207.6 | BS2: =SUMIFS(G:G, A:A, AT2, B:B, "2", D:D, "3", C:C, "A") -> 0 | BT2: =SUM('Historical Orders'!$BQ2:$BS2) -> 14127.6 | BV2: =SUMIFS(G:G, A:A, AT2, B:B, "2", D:D, "1", C:C, "B") -> 0 | BW2: =SUMIFS(G:G, A:A, AT2, B:B, "2", D:D, "2", C:C, "B") -> 0 | BX2: =SUMIFS(G:G, A:A, AT2, B:B, "2", D:D, "3", C:C, "B") -> 21048.8 | BY2: =SUM('Historical Orders'!$BV2:$BX2) -> 21048.8 | CA2: =COUNTIFS(A:A, AT2, B:B, "1") -> 3 | CB2: =COUNTIFS(A:A, AT2, B:B, "2") -> 3 | CC2: =COUNTIFS(A:A, AT2, C:C, "A") -> 4 | CD2: =COUNTIFS(A:A, AT2, C:C, "B") -> 2 | CE2: =COUNTIFS(A:A, AT2, D:D, "1") -> 2 | CF2: =COUNTIFS(A:A, AT2, D:D, "2") -> 2 | CG2: =COUNTIFS(A:A, AT2, D:D, "3") -> 2
A3: 41855 | B3: 1 | C3: A | D3: 2 | E3: 5006 | F3: 1.2 | G3: 6007.2 | H3: =SUMIFS('Historical Orders'!$E3, 'Historical Orders'!$D3, "1", 'Historical Orders'!$C3, "A", 'Historical Orders'!$B3, "1") -> 0 | I3: =SUMIFS('Historical Orders'!$G3, 'Historical Orders'!$D3, "1", 'Historical Orders'!$C3, "A", 'Historical Orders'!$B3, "1") -> 0 | J3: =SUMIFS('Historical Orders'!$E3, 'Historical Orders'!$D3, "1", 'Historical Orders'!$C3, "B", 'Historical Orders'!$B3, "1") -> 0 | K3: =SUMIFS('Historical Orders'!$G3, 'Historical Orders'!$D3, "1", 'Historical Orders'!$C3, "B", 'Historical Orders'!$B3, "1") -> 0 | L3: =SUMIFS('Historical Orders'!$E3, 'Historical Orders'!$D3, "1", 'Historical Orders'!$C3, "A", 'Historical Orders'!$B3, "2") -> 0 | M3: =SUMIFS('Historical Orders'!$G3, 'Historical Orders'!$D3, "1", 'Historical Orders'!$C3, "A", 'Historical Orders'!$B3, "2") -> 0 | N3: =SUMIFS('Historical Orders'!$E3, 'Historical Orders'!$D3, "1", 'Historical Orders'!$C3, "B", 'Historical Orders'!$B3, "2") -> 0 | O3: =SUMIFS('Historical Orders'!$G3, 'Historical Orders'!$D3, "1", 'Historical Orders'!$C3, "B", 'Historical Orders'!$B3, "2") -> 0 | P3: =SUMIFS('Historical Orders'!$E3, 'Historical Orders'!$D3, "2", 'Historical Orders'!$C3, "A", 'Historical Orders'!$B3, "1") -> 5006 | Q3: =SUMIFS('Historical Orders'!$G3, 'Historical Orders'!$D3, "2", 'Historical Orders'!$C3, "A", 'Historical Orders'!$B3, "1") -> 6007.2 | R3: =SUMIFS('Historical Orders'!$E3, 'Historical Orders'!$D3, "2", 'Historical Orders'!$C3, "B", 'Historical Orders'!$B3, "1") -> 0 | S3: =SUMIFS('Historical Orders'!$G3, 'Historical Orders'!$D3, "2", 'Historical Orders'!$C3, "B", 'Historical Orders'!$B3, "1") -> 0 | T3: =SUMIFS('Historical Orders'!$E3, 'Historical Orders'!$D3, "2", 'Historical Orders'!$C3, "A", 'Historical Orders'!$B3, "2") -> 0 | U3: =SUMIFS('Historical Orders'!$G3, 'Historical Orders'!$D3, "2", 'Historical Orders'!$C3, "A", 'Historical Orders'!$B3, "2") -> 0 | V3: =SUMIFS('Historical Orders'!$E3, 'Historical Orders'!$D3, "2", 'Historical Orders'!$C3, "B", 'Historical Orders'!$B3, "2") -> 0 | W3: =SUMIFS('Historical Orders'!$G3, 'Historical Orders'!$D3, "2", 'Historical Orders'!$C3, "B", 'Historical Orders'!$B3, "2") -> 0 | X3: =SUMIFS('Historical Orders'!$E3, 'Historical Orders'!$D3, "3", 'Historical Orders'!$C3, "A", 'Historical Orders'!$B3, "1") -> 0 | Y3: =SUMIFS('Historical Orders'!$G3, 'Historical Orders'!$D3, "3", 'Historical Orders'!$C3, "A", 'Historical Orders'!$B3, "1") -> 0 | Z3: =SUMIFS('Historical Orders'!$E3, 'Historical Orders'!$D3, "3", 'Historical Orders'!$C3, "B", 'Historical Orders'!$B3, "1") -> 0 | AA3: =SUMIFS('Historical Orders'!$G3, 'Historical Orders'!$D3, "3", 'Historical Orders'!$C3, "B", 'Historical Orders'!$B3, "1") -> 0 | AB3: =SUMIFS('Historical Orders'!$E3, 'Historical Orders'!$D3, "3", 'Historical Orders'!$C3, "A", 'Historical Orders'!$B3, "2") -> 0 | AC3: =SUMIFS('Historical Orders'!$G3, 'Historical Orders'!$D3, "3", 'Historical Orders'!$C3, "A", 'Historical Orders'!$B3, "2") -> 0 | AD3: =SUMIFS('Historical Orders'!$E3, 'Historical Orders'!$D3, "3", 'Historical Orders'!$C3, "B", 'Historical Orders'!$B3, "2") -> 0 | AE3: =SUMIFS('Historical Orders'!$G3, 'Historical Orders'!$D3, "3", 'Historical Orders'!$C3, "B", 'Historical Orders'!$B3, "2") -> 0 | AF3: =SUMIFS('Historical Orders'!$E3, 'Historical Orders'!$D3, "4", 'Historical Orders'!$C3, "A", 'Historical Orders'!$B3, "1") -> 0 | AG3: =SUMIFS('Historical Orders'!$G3, 'Historical Orders'!$D3, "4", 'Historical Orders'!$C3, "A", 'Historical Orders'!$B3, "1") -> 0 | AH3: =SUMIFS('Historical Orders'!$E3, 'Historical Orders'!$D3, "4", 'Historical Orders'!$C3, "B", 'Historical Orders'!$B3, "1") -> 0 | AI3: =SUMIFS('Historical Orders'!$G3, 'Historical Orders'!$D3, "4", 'Historical Orders'!$C3, "B", 'Historical Orders'!$B3, "1") -> 0 | AJ3: =SUMIFS('Historical Orders'!$E3, 'Historical Orders'!$D3, "4", 'Historical Orders'!$C3, "A", 'Historical Orders'!$B3, "2") -> 0 | AK3: =SUMIFS('Historical Orders'!$G3, 'Historical Orders'!$D3, "4", 'Historical Orders'!$C3, "A", 'Historical Orders'!$B3, "2") -> 0 | AL3: =SUMIFS('Historical Orders'!$E3, 'Historical Orders'!$D3, "4", 'Historical Orders'!$C3, "B", 'Historical Orders'!$B3, "2") -> 0 | AM3: =SUMIFS('Historical Orders'!$G3, 'Historical Orders'!$D3, "4", 'Historical Orders'!$C3, "B", 'Historical Orders'!$B3, "2") -> 0 | AN3: =SUMIFS('Historical Orders'!$G3, 'Historical Orders'!$C3, "A", 'Historical Orders'!$B3, "1") -> 6007.2 | AO3: =SUMIFS('Historical Orders'!$G3, 'Historical Orders'!$C3, "B", 'Historical Orders'!$B3, "1") -> 0 | AP3: =SUMIFS('Historical Orders'!$G3, 'Historical Orders'!$C3, "A", 'Historical Orders'!$B3, "2") -> 0 | AQ3: =SUMIFS('Historical Orders'!$G3, 'Historical Orders'!$C3, "B", 'Historical Orders'!$B3, "2") -> 0 | AT3: 41862 | AV3: =AT3 -> 41862 | AW3: =SUMIFS(E:E, A:A, AT3) -> 22097 | AX3: =SUMIFS(E:E, A:A, AT3, B:B, "1") -> 11799 | AY3: =SUMIFS(E:E, A:A, AT3, B:B, "2") -> 10298 | AZ3: =SUMIFS(E:E, A:A, AT3, C:C, "A") -> 18343 | BA3: =SUMIFS(E:E, A:A, AT3, C:C, "B") -> 3754 | BC3: =SUMIFS(G:G, A:A, AT3) -> 61001.8 | BD3: =SUMIFS(G:G, A:A, AT3, B:B, "1") -> 31096.6 | BE3: =SUMIFS(G:G, A:A, AT3, B:B, "2") -> 29905.2 | BG3: =SUMIFS(G:G, A:A, AT3, B:B, "1", D:D, "1", C:C, "A") -> 10115.6 | BH3: =SUMIFS(G:G, A:A, AT3, B:B, "1", D:D, "2", C:C, "A") -> 6555.6 | BI3: =SUMIFS(G:G, A:A, AT3, B:B, "1", D:D, "3", C:C, "A") -> 0 | BJ3: =SUM('Historical Orders'!$BG3:$BI3) -> 16671.2 | BL3: =SUMIFS(G:G, A:A, AT3, B:B, "1", D:D, "1", C:C, "B") -> 0 | BM3: =SUMIFS(G:G, A:A, AT3, B:B, "1", D:D, "2", C:C, "B") -> 0 | BN3: =SUMIFS(G:G, A:A, AT3, B:B, "1", D:D, "3", C:C, "B") -> 14425.4 | BO3: =SUM('Historical Orders'!$BL3:$BN3) -> 14425.4 | BQ3: =SUMIFS(G:G, A:A, AT3, B:B, "2", D:D, "1", C:C, "A") -> 7114.8 | BR3: =SUMIFS(G:G, A:A, AT3, B:B, "2", D:D, "2", C:C, "A") -> 6057.6 | BS3: =SUMIFS(G:G, A:A, AT3, B:B, "2", D:D, "3", C:C, "A") -> 0 | BT3: =SUM('Historical Orders'!$BQ3:$BS3) -> 13172.4 | BV3: =SUMIFS(G:G, A:A, AT3, B:B, "2", D:D, "1", C:C, "B") -> 0 | BW3: =SUMIFS(G:G, A:A, AT3, B:B, "2", D:D, "2", C:C, "B") -> 0 | BX3: =SUMIFS(G:G, A:A, AT3, B:B, "2", D:D, "3", C:C, "B") -> 16732.8 | BY3: =SUM('Historical Orders'!$BV3:$BX3) -> 16732.8 | CA3: =COUNTIFS(A:A, AT3, B:B, "1") -> 3 | CB3: =COUNTIFS(A:A, AT3, B:B, "2") -> 3 | CC3: =COUNTIFS(A:A, AT3, C:C, "A") -> 4 | CD3: =COUNTIFS(A:A, AT3, C:C, "B") -> 2 | CE3: =COUNTIFS(A:A, AT3, D:D, "1") -> 2 | CF3: =COUNTIFS(A:A, AT3, D:D, "2") -> 2 | CG3: =COUNTIFS(A:A, AT3, D:D, "3") -> 2
A4: 41855 | B4: 2 | C4: A | D4: 1 | E4: 3600 | F4: 2.2 | G4: 7920 | H4: =SUMIFS('Historical Orders'!$E4, 'Historical Orders'!$D4, "1", 'Historical Orders'!$C4, "A", 'Historical Orders'!$B4, "1") -> 0 | I4: =SUMIFS('Historical Orders'!$G4, 'Historical Orders'!$D4, "1", 'Historical Orders'!$C4, "A", 'Historical Orders'!$B4, "1") -> 0 | J4: =SUMIFS('Historical Orders'!$E4, 'Historical Orders'!$D4, "1", 'Historical Orders'!$C4, "B", 'Historical Orders'!$B4, "1") -> 0 | K4: =SUMIFS('Historical Orders'!$G4, 'Historical Orders'!$D4, "1", 'Historical Orders'!$C4, "B", 'Historical Orders'!$B4, "1") -> 0 | L4: =SUMIFS('Historical Orders'!$E4, 'Historical Orders'!$D4, "1", 'Historical Orders'!$C4, "A", 'Historical Orders'!$B4, "2") -> 3600 | M4: =SUMIFS('Historical Orders'!$G4, 'Historical Orders'!$D4, "1", 'Historical Orders'!$C4, "A", 'Historical Orders'!$B4, "2") -> 7920 | N4: =SUMIFS('Historical Orders'!$E4, 'Historical Orders'!$D4, "1", 'Historical Orders'!$C4, "B", 'Historical Orders'!$B4, "2") -> 0 | O4: =SUMIFS('Historical Orders'!$G4, 'Historical Orders'!$D4, "1", 'Historical Orders'!$C4, "B", 'Historical Orders'!$B4, "2") -> 0 | P4: =SUMIFS('Historical Orders'!$E4, 'Historical Orders'!$D4, "2", 'Historical Orders'!$C4, "A", 'Historical Orders'!$B4, "1") -> 0 | Q4: =SUMIFS('Historical Orders'!$G4, 'Historical Orders'!$D4, "2", 'Historical Orders'!$C4, "A", 'Historical Orders'!$B4, "1") -> 0 | R4: =SUMIFS('Historical Orders'!$E4, 'Historical Orders'!$D4, "2", 'Historical Orders'!$C4, "B", 'Historical Orders'!$B4, "1") -> 0 | S4: =SUMIFS('Historical Orders'!$G4, 'Historical Orders'!$D4, "2", 'Historical Orders'!$C4, "B", 'Historical Orders'!$B4, "1") -> 0 | T4: =SUMIFS('Historical Orders'!$E4, 'Historical Orders'!$D4, "2", 'Historical Orders'!$C4, "A", 'Historical Orders'!$B4, "2") -> 0 | U4: =SUMIFS('Historical Orders'!$G4, 'Historical Orders'!$D4, "2", 'Historical Orders'!$C4, "A", 'Historical Orders'!$B4, "2") -> 0 | V4: =SUMIFS('Historical Orders'!$E4, 'Historical Orders'!$D4, "2", 'Historical Orders'!$C4, "B", 'Historical Orders'!$B4, "2") -> 0 | W4: =SUMIFS('Historical Orders'!$G4, 'Historical Orders'!$D4, "2", 'Historical Orders'!$C4, "B", 'Historical Orders'!$B4, "2") -> 0 | X4: =SUMIFS('Historical Orders'!$E4, 'Historical Orders'!$D4, "3", 'Historical Orders'!$C4, "A", 'Historical Orders'!$B4, "1") -> 0 | Y4: =SUMIFS('Historical Orders'!$G4, 'Historical Orders'!$D4, "3", 'Historical Orders'!$C4, "A", 'Historical Orders'!$B4, "1") -> 0 | Z4: =SUMIFS('Historical Orders'!$E4, 'Historical Orders'!$D4, "3", 'Historical Orders'!$C4, "B", 'Historical Orders'!$B4, "1") -> 0 | AA4: =SUMIFS('Historical Orders'!$G4, 'Historical Orders'!$D4, "3", 'Historical Orders'!$C4, "B", 'Historical Orders'!$B4, "1") -> 0 | AB4: =SUMIFS('Historical Orders'!$E4, 'Historical Orders'!$D4, "3", 'Historical Orders'!$C4, "A", 'Historical Orders'!$B4, "2") -> 0 | AC4: =SUMIFS('Historical Orders'!$G4, 'Historical Orders'!$D4, "3", 'Historical Orders'!$C4, "A", 'Historical Orders'!$B4, "2") -> 0 | AD4: =SUMIFS('Historical Orders'!$E4, 'Historical Orders'!$D4, "3", 'Historical Orders'!$C4, "B", 'Historical Orders'!$B4, "2") -> 0 | AE4: =SUMIFS('Historical Orders'!$G4, 'Historical Orders'!$D4, "3", 'Historical Orders'!$C4, "B", 'Historical Orders'!$B4, "2") -> 0 | AF4: =SUMIFS('Historical Orders'!$E4, 'Historical Orders'!$D4, "4", 'Historical Orders'!$C4, "A", 'Historical Orders'!$B4, "1") -> 0 | AG4: =SUMIFS('Historical Orders'!$G4, 'Historical Orders'!$D4, "4", 'Historical Orders'!$C4, "A", 'Historical Orders'!$B4, "1") -> 0 | AH4: =SUMIFS('Historical Orders'!$E4, 'Historical Orders'!$D4, "4", 'Historical Orders'!$C4, "B", 'Historical Orders'!$B4, "1") -> 0 | AI4: =SUMIFS('Historical Orders'!$G4, 'Historical Orders'!$D4, "4", 'Historical Orders'!$C4, "B", 'Historical Orders'!$B4, "1") -> 0 | AJ4: =SUMIFS('Historical Orders'!$E4, 'Historical Orders'!$D4, "4", 'Historical Orders'!$C4, "A", 'Historical Orders'!$B4, "2") -> 0 | AK4: =SUMIFS('Historical Orders'!$G4, 'Historical Orders'!$D4, "4", 'Historical Orders'!$C4, "A", 'Historical Orders'!$B4, "2") -> 0 | AL4: =SUMIFS('Historical Orders'!$E4, 'Historical Orders'!$D4, "4", 'Historical Orders'!$C4, "B", 'Historical Orders'!$B4, "2") -> 0 | AM4: =SUMIFS('Historical Orders'!$G4, 'Historical Orders'!$D4, "4", 'Historical Orders'!$C4, "B", 'Historical Orders'!$B4, "2") -> 0 | AN4: =SUMIFS('Historical Orders'!$G4, 'Historical Orders'!$C4, "A", 'Historical Orders'!$B4, "1") -> 0 | AO4: =SUMIFS('Historical Orders'!$G4, 'Historical Orders'!$C4, "B", 'Historical Orders'!$B4, "1") -> 0 | AP4: =SUMIFS('Historical Orders'!$G4, 'Historical Orders'!$C4, "A", 'Historical Orders'!$B4, "2") -> 7920 | AQ4: =SUMIFS('Historical Orders'!$G4, 'Historical Orders'!$C4, "B", 'Historical Orders'!$B4, "2") -> 0 | AT4: 41869 | AV4: =AT4 -> 41869 | AW4: =SUMIFS(E:E, A:A, AT4) -> 21300 | AX4: =SUMIFS(E:E, A:A, AT4, B:B, "1") -> 11392 | AY4: =SUMIFS(E:E, A:A, AT4, B:B, "2") -> 9908 | AZ4: =SUMIFS(E:E, A:A, AT4, C:C, "A") -> 17141 | BA4: =SUMIFS(E:E, A:A, AT4, C:C, "B") -> 4159 | BC4: =SUMIFS(G:G, A:A, AT4) -> 61979.9 | BD4: =SUMIFS(G:G, A:A, AT4, B:B, "1") -> 30590.6 | BE4: =SUMIFS(G:G, A:A, AT4, B:B, "2") -> 31389.3 | BG4: =SUMIFS(G:G, A:A, AT4, B:B, "1", D:D, "1", C:C, "A") -> 9389.6 | BH4: =SUMIFS(G:G, A:A, AT4, B:B, "1", D:D, "2", C:C, "A") -> 6410.4 | BI4: =SUMIFS(G:G, A:A, AT4, B:B, "1", D:D, "3", C:C, "A") -> 0 | BJ4: =SUM('Historical Orders'!$BG4:$BI4) -> 15800 | BL4: =SUMIFS(G:G, A:A, AT4, B:B, "1", D:D, "1", C:C, "B") -> 0 | BM4: =SUMIFS(G:G, A:A, AT4, B:B, "1", D:D, "2", C:C, "B") -> 0 | BN4: =SUMIFS(G:G, A:A, AT4, B:B, "1", D:D, "3", C:C, "B") -> 14790.6 | BO4: =SUM('Historical Orders'!$BL4:$BN4) -> 14790.6 | BQ4: =SUMIFS(G:G, A:A, AT4, B:B, "2", D:D, "1", C:C, "A") -> 5770.6 | BR4: =SUMIFS(G:G, A:A, AT4, B:B, "2", D:D, "2", C:C, "A") -> 5889.6 | BS4: =SUMIFS(G:G, A:A, AT4, B:B, "2", D:D, "3", C:C, "A") -> 0 | BT4: =SUM('Historical Orders'!$BQ4:$BS4) -> 11660.2 | BV4: =SUMIFS(G:G, A:A, AT4, B:B, "2", D:D, "1", C:C, "B") -> 0 | BW4: =SUMIFS(G:G, A:A, AT4, B:B, "2", D:D, "2", C:C, "B") -> 0 | BX4: =SUMIFS(G:G, A:A, AT4, B:B, "2", D:D, "3", C:C, "B") -> 19729.1 | BY4: =SUM('Historical Orders'!$BV4:$BX4) -> 19729.1 | CA4: =COUNTIFS(A:A, AT4, B:B, "1") -> 3 | CB4: =COUNTIFS(A:A, AT4, B:B, "2") -> 3 | CC4: =COUNTIFS(A:A, AT4, C:C, "A") -> 4 | CD4: =COUNTIFS(A:A, AT4, C:C, "B") -> 2 | CE4: =COUNTIFS(A:A, AT4, D:D, "1") -> 2 | CF4: =COUNTIFS(A:A, AT4, D:D, "2") -> 2 | CG4: =COUNTIFS(A:A, AT4, D:D, "3") -> 2
A5: 41855 | B5: 2 | C5: A | D5: 2 | E5: 5173 | F5: 1.2 | G5: 6207.6 | H5: =SUMIFS('Historical Orders'!$E5, 'Historical Orders'!$D5, "1", 'Historical Orders'!$C5, "A", 'Historical Orders'!$B5, "1") -> 0 | I5: =SUMIFS('Historical Orders'!$G5, 'Historical Orders'!$D5, "1", 'Historical Orders'!$C5, "A", 'Historical Orders'!$B5, "1") -> 0 | J5: =SUMIFS('Historical Orders'!$E5, 'Historical Orders'!$D5, "1", 'Historical Orders'!$C5, "B", 'Historical Orders'!$B5, "1") -> 0 | K5: =SUMIFS('Historical Orders'!$G5, 'Historical Orders'!$D5, "1", 'Historical Orders'!$C5, "B", 'Historical Orders'!$B5, "1") -> 0 | L5: =SUMIFS('Historical Orders'!$E5, 'Historical Orders'!$D5, "1", 'Historical Orders'!$C5, "A", 'Historical Orders'!$B5, "2") -> 0 | M5: =SUMIFS('Historical Orders'!$G5, 'Historical Orders'!$D5, "1", 'Historical Orders'!$C5, "A", 'Historical Orders'!$B5, "2") -> 0 | N5: =SUMIFS('Historical Orders'!$E5, 'Historical Orders'!$D5, "1", 'Historical Orders'!$C5, "B", 'Historical Orders'!$B5, "2") -> 0 | O5: =SUMIFS('Historical Orders'!$G5, 'Historical Orders'!$D5, "1", 'Historical Orders'!$C5, "B", 'Historical Orders'!$B5, "2") -> 0 | P5: =SUMIFS('Historical Orders'!$E5, 'Historical Orders'!$D5, "2", 'Historical Orders'!$C5, "A", 'Historical Orders'!$B5, "1") -> 0 | Q5: =SUMIFS('Historical Orders'!$G5, 'Historical Orders'!$D5, "2", 'Historical Orders'!$C5, "A", 'Historical Orders'!$B5, "1") -> 0 | R5: =SUMIFS('Historical Orders'!$E5, 'Historical Orders'!$D5, "2", 'Historical Orders'!$C5, "B", 'Historical Orders'!$B5, "1") -> 0 | S5: =SUMIFS('Historical Orders'!$G5, 'Historical Orders'!$D5, "2", 'Historical Orders'!$C5, "B", 'Historical Orders'!$B5, "1") -> 0 | T5: =SUMIFS('Historical Orders'!$E5, 'Historical Orders'!$D5, "2", 'Historical Orders'!$C5, "A", 'Historical Orders'!$B5, "2") -> 5173 | U5: =SUMIFS('Historical Orders'!$G5, 'Historical Orders'!$D5, "2", 'Historical Orders'!$C5, "A", 'Historical Orders'!$B5, "2") -> 6207.6 | V5: =SUMIFS('Historical Orders'!$E5, 'Historical Orders'!$D5, "2", 'Historical Orders'!$C5, "B", 'Historical Orders'!$B5, "2") -> 0 | W5: =SUMIFS('Historical Orders'!$G5, 'Historical Orders'!$D5, "2", 'Historical Orders'!$C5, "B", 'Historical Orders'!$B5, "2") -> 0 | X5: =SUMIFS('Historical Orders'!$E5, 'Historical Orders'!$D5, "3", 'Historical Orders'!$C5, "A", 'Historical Orders'!$B5, "1") -> 0 | Y5: =SUMIFS('Historical Orders'!$G5, 'Historical Orders'!$D5, "3", 'Historical Orders'!$C5, "A", 'Historical Orders'!$B5, "1") -> 0 | Z5: =SUMIFS('Historical Orders'!$E5, 'Historical Orders'!$D5, "3", 'Historical Orders'!$C5, "B", 'Historical Orders'!$B5, "1") -> 0 | AA5: =SUMIFS('Historical Orders'!$G5, 'Historical Orders'!$D5, "3", 'Historical Orders'!$C5, "B", 'Historical Orders'!$B5, "1") -> 0 | AB5: =SUMIFS('Historical Orders'!$E5, 'Historical Orders'!$D5, "3", 'Historical Orders'!$C5, "A", 'Historical Orders'!$B5, "2") -> 0 | AC5: =SUMIFS('Historical Orders'!$G5, 'Historical Orders'!$D5, "3", 'Historical Orders'!$C5, "A", 'Historical Orders'!$B5, "2") -> 0 | AD5: =SUMIFS('Historical Orders'!$E5, 'Historical Orders'!$D5, "3", 'Historical Orders'!$C5, "B", 'Historical Orders'!$B5, "2") -> 0 | AE5: =SUMIFS('Historical Orders'!$G5, 'Historical Orders'!$D5, "3", 'Historical Orders'!$C5, "B", 'Historical Orders'!$B5, "2") -> 0 | AF5: =SUMIFS('Historical Orders'!$E5, 'Historical Orders'!$D5, "4", 'Historical Orders'!$C5, "A", 'Historical Orders'!$B5, "1") -> 0 | AG5: =SUMIFS('Historical Orders'!$G5, 'Historical Orders'!$D5, "4", 'Historical Orders'!$C5, "A", 'Historical Orders'!$B5, "1") -> 0 | AH5: =SUMIFS('Historical Orders'!$E5, 'Historical Orders'!$D5, "4", 'Historical Orders'!$C5, "B", 'Historical Orders'!$B5, "1") -> 0 | AI5: =SUMIFS('Historical Orders'!$G5, 'Historical Orders'!$D5, "4", 'Historical Orders'!$C5, "B", 'Historical Orders'!$B5, "1") -> 0 | AJ5: =SUMIFS('Historical Orders'!$E5, 'Historical Orders'!$D5, "4", 'Historical Orders'!$C5, "A", 'Historical Orders'!$B5, "2") -> 0 | AK5: =SUMIFS('Historical Orders'!$G5, 'Historical Orders'!$D5, "4", 'Historical Orders'!$C5, "A", 'Historical Orders'!$B5, "2") -> 0 | AL5: =SUMIFS('Historical Orders'!$E5, 'Historical Orders'!$D5, "4", 'Historical Orders'!$C5, "B", 'Historical Orders'!$B5, "2") -> 0 | AM5: =SUMIFS('Historical Orders'!$G5, 'Historical Orders'!$D5, "4", 'Historical Orders'!$C5, "B", 'Historical Orders'!$B5, "2") -> 0 | AN5: =SUMIFS('Historical Orders'!$G5, 'Historical Orders'!$C5, "A", 'Historical Orders'!$B5, "1") -> 0 | AO5: =SUMIFS('Historical Orders'!$G5, 'Historical Orders'!$C5, "B", 'Historical Orders'!$B5, "1") -> 0 | AP5: =SUMIFS('Historical Orders'!$G5, 'Historical Orders'!$C5, "A", 'Historical Orders'!$B5, "2") -> 6207.6 | AQ5: =SUMIFS('Historical Orders'!$G5, 'Historical Orders'!$C5, "B", 'Historical Orders'!$B5, "2") -> 0 | AT5: 41876 | AV5: =AT5 -> 41876 | AW5: =SUMIFS(E:E, A:A, AT5) -> 23334 | AX5: =SUMIFS(E:E, A:A, AT5, B:B, "1") -> 12071 | AY5: =SUMIFS(E:E, A:A, AT5, B:B, "2") -> 11263 | AZ5: =SUMIFS(E:E, A:A, AT5, C:C, "A") -> 17374 | BA5: =SUMIFS(E:E, A:A, AT5, C:C, "B") -> 5960 | BC5: =SUMIFS(G:G, A:A, AT5) -> 75671.8 | BD5: =SUMIFS(G:G, A:A, AT5, B:B, "1") -> 35709.5 | BE5: =SUMIFS(G:G, A:A, AT5, B:B, "2") -> 39962.3 | BG5: =SUMIFS(G:G, A:A, AT5, B:B, "1", D:D, "1", C:C, "A") -> 7596.6 | BH5: =SUMIFS(G:G, A:A, AT5, B:B, "1", D:D, "2", C:C, "A") -> 7338 | BI5: =SUMIFS(G:G, A:A, AT5, B:B, "1", D:D, "3", C:C, "A") -> 0 | BJ5: =SUM('Historical Orders'!$BG5:$BI5) -> 14934.6 | BL5: =SUMIFS(G:G, A:A, AT5, B:B, "1", D:D, "1", C:C, "B") -> 0 | BM5: =SUMIFS(G:G, A:A, AT5, B:B, "1", D:D, "2", C:C, "B") -> 0 | BN5: =SUMIFS(G:G, A:A, AT5, B:B, "1", D:D, "3", C:C, "B") -> 20774.9 | BO5: =SUM('Historical Orders'!$BL5:$BN5) -> 20774.9 | BQ5: =SUMIFS(G:G, A:A, AT5, B:B, "2", D:D, "1", C:C, "A") -> 4184.4 | BR5: =SUMIFS(G:G, A:A, AT5, B:B, "2", D:D, "2", C:C, "A") -> 7084.8 | BS5: =SUMIFS(G:G, A:A, AT5, B:B, "2", D:D, "3", C:C, "A") -> 0 | BT5: =SUM('Historical Orders'!$BQ5:$BS5) -> 11269.2 | BV5: =SUMIFS(G:G, A:A, AT5, B:B, "2", D:D, "1", C:C, "B") -> 0 | BW5: =SUMIFS(G:G, A:A, AT5, B:B, "2", D:D, "2", C:C, "B") -> 0 | BX5: =SUMIFS(G:G, A:A, AT5, B:B, "2", D:D, "3", C:C, "B") -> 28693.1 | BY5: =SUM('Historical Orders'!$BV5:$BX5) -> 28693.1 | CA5: =COUNTIFS(A:A, AT5, B:B, "1") -> 3 | CB5: =COUNTIFS(A:A, AT5, B:B, "2") -> 3 | CC5: =COUNTIFS(A:A, AT5, C:C, "A") -> 4 | CD5: =COUNTIFS(A:A, AT5, C:C, "B") -> 2 | CE5: =COUNTIFS(A:A, AT5, D:D, "1") -> 2 | CF5: =COUNTIFS(A:A, AT5, D:D, "2") -> 2 | CG5: =COUNTIFS(A:A, AT5, D:D, "3") -> 2
